Workbook

Sheet Leyenda
A1: Matriz de trazabilidad TI-Desk · Requisito → Historia → Escenario Gherkin → Caso de prueba → Prueba automatizada
A2: Propietaria: Melisa (Product Owner) · Octubre 2026 · Fuente de los escenarios: Product Backlog priorizado v1.1
A4: Cómo se llena
A5: 1. Las columnas H (Caso(s) de prueba) e I (Prueba automatizada) están en azul con fondo amarillo: son las únicas que se editan.
A6: 2. La columna H ya viene prellenada con los CP del Plan de pruebas v1 de Brenda (CP-001 a CP-048). Si un escenario tiene varios, se separan con coma; una celda vacía es un hueco de cobertura.
A7: 3. En I se anota la clase y el método de la prueba automatizada, cuando exista. Todavía está vacía porque las pruebas se escriben a lo largo de los sprints.
A8: 5. La columna Observación señala los huecos de cobertura y las diferencias entre el plan y el backlog.
A9: 4. La columna Estado y la hoja Resumen se calculan solas; no se editan.
A11: Ejemplo de llenado (no es un dato real)
A12: Escenario "Registro exitoso" (RF-01, HU-01) → H: CP-001, CP-002 · I: AuthControllerTest.registroExitoso
A14: Supuestos
A15: • Un escenario cuenta como "con caso de prueba" cuando H no está vacía, y como "automatizado" cuando I no está vacía.
... A19: • Criterio de aceptación para el parcial: cada requisito M y S con al menos una prueba automatizada (anteproyecto, sección 8).

Sheet Trazabilidad
A1: Requisito | B1: Historia | C1: Prio. | D1: Sprint | E1: Dueño de la historia | F1: Escenario Gherkin (Backlog v1.1) | G1: Tipo | H1: Caso(s) de prueba (CP) | I1: Prueba automatizada | J1: Estado | K1: Observación
A2: RF-01 | B2: HU-01 | C2: M | D2: 1 | E2: Sashi | F2: Registro exitoso | G2: Positivo | H2: CP-001 | J2: =IF(H2="","Sin caso de prueba",IF(I2="","Con caso, sin automatizar","Automatizada")) -> Con caso, sin automatizar
A3: RF-01 | B3: HU-01 | C3: M | D3: 1 | E3: Sashi | F3: Correo duplicado | G3: Negativo | H3: CP-002 | J3: =IF(H3="","Sin caso de prueba",IF(I3="","Con caso, sin automatizar","Automatizada")) -> Con caso, sin automatizar | K3: El CP-002 dice "409 o 400"; el backlog exige 409. Pedir a Brenda que lo precise.
A4: RF-01 | B4: HU-01 | C4: M | D4: 1 | E4: Sashi | F4: Datos inválidos | G4: Negativo | H4: CP-003 | J4: =IF(H4="","Sin caso de prueba",IF(I4="","Con caso, sin automatizar","Automatizada")) -> Con caso, sin automatizar
A5: RF-02 | B5: HU-02 | C5: M | D5: 1 | E5: Sashi | F5: Login correcto | G5: Positivo | H5: CP-004 | J5: =IF(H5="","Sin caso de prueba",IF(I5="","Con caso, sin automatizar","Automatizada")) -> Con caso, sin automatizar
A6: RF-02 | B6: HU-02 | C6: M | D6: 1 | E6: Sashi | F6: Credenciales incorrectas | G6: Negativo | H6: CP-005 | J6: =IF(H6="","Sin caso de prueba",IF(I6="","Con caso, sin automatizar","Automatizada")) -> Con caso, sin automatizar
A7: RF-02 | B7: HU-02 | C7: M | D7: 1 | E7: Sashi | F7: Token vencido | G7: Negativo | H7: CP-006 | J7: =IF(H7="","Sin caso de prueba",IF(I7="","Con caso, sin automatizar","Automatizada")) -> Con caso, sin automatizar
A8: RF-03 | B8: HU-03 | C8: M | D8: 1 | E8: Sashi | F8: Cambiar rol | G8: Positivo | H8: CP-007 | J8: =IF(H8="","Sin caso de prueba",IF(I8="","Con caso, sin automatizar","Automatizada")) -> Con caso, sin automatizar
A9: RF-03 | B9: HU-03 | C9: M | D9: 1 | E9: Sashi | F9: Desactivar usuario | G9: Positivo | H9: CP-009 | J9: =IF(H9="","Sin caso de prueba",IF(I9="","Con caso, sin automatizar","Automatizada")) -> Con caso, sin automatizar
A10: RF-03 | B10: HU-03 | C10: M | D10: 1 | E10: Sashi | F10: Sin permiso | G10: Negativo | H10: CP-008 | J10: =IF(H10="","Sin caso de prueba",IF(I10="","Con caso, sin automatizar","Automatizada")) -> Con caso, sin automatizar
A11: RF-04 | B11: HU-04 | C11: M | D11: 1 | E11: Ulises | F11: Creación exitosa | G11: Positivo | H11: CP-010, CP-012 | J11: =IF(H11="","Sin caso de prueba",IF(I11="","Con caso, sin automatizar","Automatizada")) -> Con caso, sin automatizar | K11: CP-012 cubre folios únicos.
A12: RF-04 | B12: HU-04 | C12: M | D12: 1 | E12: Ulises | F12: Ticket ligado a un activo | G12: Positivo | H12: CP-040 | J12: =IF(H12="","Sin caso de prueba",IF(I12="","Con caso, sin automatizar","Automatizada")) -> Con caso, sin automatizar
A13: RF-04 | B13: HU-04 | C13: M | D13: 1 | E13: Ulises | F13: Campos obligatorios faltantes | G13: Negativo | H13: CP-011 | J13: =IF(H13="","Sin caso de prueba",IF(I13="","Con caso, sin automatizar","Automatizada")) -> Con caso, sin automatizar
A14: RF-04 | B14: HU-04 | C14: M | D14: 1 | E14: Ulises | F14: Activo inexistente | G14: Negativo | J14: =IF(H14="","Sin caso de prueba",IF(I14="","Con caso, sin automatizar","Automatizada")) -> Sin caso de prueba | K14: SIN CASO DE PRUEBA: pedir a Brenda un CP nuevo.
A15: RF-04 | B15: HU-04 | C15: M | D15: 1 | E15: Ulises | F15: Activo dado de baja (por confirmar con Ulises) | G15: Negativo | J15: =IF(H15="","Sin caso de prueba",IF(I15="","Con caso, sin automatizar","Automatizada")) -> Sin caso de prueba | K15: SIN CASO DE PRUEBA: regla por confirmar con Ulises antes de pedir el CP.
A16: RF-05 | B16: HU-05 | C16: M | D16: 1 | E16: Ulises | F16: Visibilidad del usuario | G16: Positivo | H16: CP-013 | J16: =IF(H16="","Sin caso de prueba",IF(I16="","Con caso, sin automatizar","Automatizada")) -> Con caso, sin automatizar
A17: RF-05 | B17: HU-05 | C17: M | D17: 1 | E17: Ulises | F17: Visibilidad del técnico | G17: Positivo | H17: CP-014 | J17: =IF(H17="","Sin caso de prueba",IF(I17="","Con caso, sin automatizar","Automatizada")) -> Con caso, sin automatizar
A18: RF-05 | B18: HU-05 | C18: M | D18: 1 | E18: Ulises | F18: Filtros y paginación | G18: Positivo | H18: CP-015 | J18: =IF(H18="","Sin caso de prueba",IF(I18="","Con caso, sin automatizar","Automatizada")) -> Con caso, sin automatizar
A19: RF-05 | B19: HU-05 | C19: M | D19: 1 | E19: Ulises | F19: Ticket ajeno | G19: Negativo | H19: CP-016 | J19: =IF(H19="","Sin caso de prueba",IF(I19="","Con caso, sin automatizar","Automatizada")) -> Con caso, sin automatizar
A20: RF-06 | B20: HU-06 | C20: M | D20: 2 | E20: Ulises | F20: Asignación por el administrador | G20: Positivo | H20: CP-017 | J20: =IF(H20="","Sin caso de prueba",IF(I20="","Con caso, sin automatizar","Automatizada")) -> Con caso, sin automatizar
A21: RF-06 | B21: HU-06 | C21: M | D21: 2 | E21: Ulises | F21: Autoasignación | G21: Positivo | H21: CP-018 | J21: =IF(H21="","Sin caso de prueba",IF(I21="","Con caso, sin automatizar","Automatizada")) -> Con caso, sin automatizar
A22: RF-06 | B22: HU-06 | C22: M | D22: 2 | E22: Ulises | F22: Conflicto de asignación simultánea | G22: Negativo | H22: CP-019 | J22: =IF(H22="","Sin caso de prueba",IF(I22="","Con caso, sin automatizar","Automatizada")) -> Con caso, sin automatizar
A23: RF-06 | B23: HU-06 | C23: M | D23: 2 | E23: Ulises | F23: Usuario sin permiso | G23: Negativo | H23: CP-042 | J23: =IF(H23="","Sin caso de prueba",IF(I23="","Con caso, sin automatizar","Automatizada")) -> Con caso, sin automatizar | K23: Cubierto por la prueba transversal de roles; conviene un CP específico.
A24: RF-07 | B24: HU-07 | C24: M | D24: 2 | E24: Ulises | F24: Comentario público | G24: Positivo | H24: CP-020 | J24: =IF(H24="","Sin caso de prueba",IF(I24="","Con caso, sin automatizar","Automatizada")) -> Con caso, sin automatizar
A25: RF-07 | B25: HU-07 | C25: M | D25: 2 | E25: Ulises | F25: Comentario interno | G25: Positivo | H25: CP-021 | J25: =IF(H25="","Sin caso de prueba",IF(I25="","Con caso, sin automatizar","Automatizada")) -> Con caso, sin automatizar
A26: RF-07 | B26: HU-07 | C26: M | D26: 2 | E26: Ulises | F26: Ticket ajeno | G26: Negativo | J26: =IF(H26="","Sin caso de prueba",IF(I26="","Con caso, sin automatizar","Automatizada")) -> Sin caso de prueba | K26: SIN CASO DE PRUEBA: el CP-016 cubre el detalle, no el comentario.
A27: RF-08 | B27: HU-08 | C27: M | D27: 2 | E27: Ulises | F27: Transición válida | G27: Positivo | H27: CP-022 | J27: =IF(H27="","Sin caso de prueba",IF(I27="","Con caso, sin automatizar","Automatizada")) -> Con caso, sin automatizar
A28: RF-08 | B28: HU-08 | C28: M | D28: 2 | E28: Ulises | F28: Transición no permitida | G28: Negativo | H28: CP-023 | J28: =IF(H28="","Sin caso de prueba",IF(I28="","Con caso, sin automatizar","Automatizada")) -> Con caso, sin automatizar
A29: RF-08 | B29: HU-08 | C29: M | D29: 2 | E29: Ulises | F29: Estados finales | G29: Negativo | H29: CP-024 | J29: =IF(H29="","Sin caso de prueba",IF(I29="","Con caso, sin automatizar","Automatizada")) -> Con caso, sin automatizar
A30: RF-08 | B30: HU-08 | C30: M | D30: 2 | E30: Ulises | F30: Técnico no asignado | G30: Negativo | H30: CP-025 | J30: =IF(H30="","Sin caso de prueba",IF(I30="","Con caso, sin automatizar","Automatizada")) -> Con caso, sin automatizar | K30: El CP-025 habla de "rol no autorizado"; precisar el caso del técnico sin asignación.
A31: RF-13 | B31: HU-09a | C31: M | D31: 2 | E31: Melisa | F31: Alta de activo | G31: Positivo | H31: CP-034 | J31: =IF(H31="","Sin caso de prueba",IF(I31="","Con caso, sin automatizar","Automatizada")) -> Con caso, sin automatizar
A32: RF-13 | B32: HU-09a | C32: M | D32: 2 | E32: Melisa | F32: Edición de activo | G32: Positivo | H32: CP-036 | J32: =IF(H32="","Sin caso de prueba",IF(I32="","Con caso, sin automatizar","Automatizada")) -> Con caso, sin automatizar
A33: RF-13 | B33: HU-09a | C33: M | D33: 2 | E33: Melisa | F33: Etiqueta duplicada | G33: Negativo | H33: CP-035 | J33: =IF(H33="","Sin caso de prueba",IF(I33="","Con caso, sin automatizar","Automatizada")) -> Con caso, sin automatizar | K33: El CP-035 dice "409 o 400"; el backlog exige 409.
A34: RF-13 | B34: HU-09a | C34: M | D34: 2 | E34: Melisa | F34: Datos inválidos | G34: Negativo | J34: =IF(H34="","Sin caso de prueba",IF(I34="","Con caso, sin automatizar","Automatizada")) -> Sin caso de prueba | K34: SIN CASO DE PRUEBA: pedir CP de validación del alta.
A35: RF-13 | B35: HU-09a | C35: M | D35: 2 | E35: Melisa | F35: Responsable inexistente | G35: Negativo | J35: =IF(H35="","Sin caso de prueba",IF(I35="","Con caso, sin automatizar","Automatizada")) -> Sin caso de prueba | K35: SIN CASO DE PRUEBA.
A36: RF-13 | B36: HU-09a | C36: M | D36: 2 | E36: Melisa | F36: Sin permiso de escritura | G36: Negativo | H36: CP-039, CP-042 | J36: =IF(H36="","Sin caso de prueba",IF(I36="","Con caso, sin automatizar","Automatizada")) -> Con caso, sin automatizar | K36: El CP-039 cubre al TECNICO; el USUARIO queda en la prueba transversal.
A37: RF-13 | B37: HU-09b | C37: M | D37: 2 | E37: Melisa | F37: Baja lógica | G37: Positivo | H37: CP-037 | J37: =IF(H37="","Sin caso de prueba",IF(I37="","Con caso, sin automatizar","Automatizada")) -> Con caso, sin automatizar | K37: El CP-037 dice "inactivo"; el estado es BAJA. Unificar el término.
A38: RF-13 | B38: HU-09b | C38: M | D38: 2 | E38: Melisa | F38: Baja por edición no permitida | G38: Negativo | J38: =IF(H38="","Sin caso de prueba",IF(I38="","Con caso, sin automatizar","Automatizada")) -> Sin caso de prueba | K38: SIN CASO DE PRUEBA.
A39: RF-13 | B39: HU-09b | C39: M | D39: 2 | E39: Melisa | F39: Activo inexistente | G39: Negativo | J39: =IF(H39="","Sin caso de prueba",IF(I39="","Con caso, sin automatizar","Automatizada")) -> Sin caso de prueba | K39: SIN CASO DE PRUEBA.
A40: RF-13 | B40: HU-09b | C40: M | D40: 2 | E40: Melisa | F40: Sin permiso | G40: Negativo | H40: CP-042 | J40: =IF(H40="","Sin caso de prueba",IF(I40="","Con caso, sin automatizar","Automatizada")) -> Con caso, sin automatizar | K40: Cubierto por la prueba transversal de roles.
...

Sheet Resumen
A1: Requisito | B1: Historias | C1: Prio. | D1: Parcial (v0.5.0) | E1: Escenarios | F1: Positivos | G1: Negativos | H1: Con CP | I1: Automatizados | J1: % con CP | K1: Alerta
A2: RF-01 | B2: HU-01 | C2: M | D2: Sí | E2: =COUNTIF(Trazabilidad!$A$2:$A$73,A2) -> 3 | F2: =COUNTIFS(Trazabilidad!$A$2:$A$73,A2,Trazabilidad!$G$2:$G$73,"Positivo") -> 1 | G2: =COUNTIFS(Trazabilidad!$A$2:$A$73,A2,Trazabilidad!$G$2:$G$73,"Negativo") -> 2 | H2: =COUNTIFS(Trazabilidad!$A$2:$A$73,A2,Trazabilidad!$H$2:$H$73,"<>") -> 3 | I2: =COUNTIFS(Trazabilidad!$A$2:$A$73,A2,Trazabilidad!$I$2:$I$73,"<>") -> 0 | J2: =IF(E2=0,0,H2/E2) -> 1 | K2: =IF(G2=0,"Falta escenario negativo",IF(F2=0,"Falta escenario positivo",IF(H2<E2,"Faltan casos de prueba","OK"))) -> OK
A3: RF-02 | B3: HU-02 | C3: M | D3: Sí | E3: =COUNTIF(Trazabilidad!$A$2:$A$73,A3) -> 3 | F3: =COUNTIFS(Trazabilidad!$A$2:$A$73,A3,Trazabilidad!$G$2:$G$73,"Positivo") -> 1 | G3: =COUNTIFS(Trazabilidad!$A$2:$A$73,A3,Trazabilidad!$G$2:$G$73,"Negativo") -> 2 | H3: =COUNTIFS(Trazabilidad!$A$2:$A$73,A3,Trazabilidad!$H$2:$H$73,"<>") -> 3 | I3: =COUNTIFS(Trazabilidad!$A$2:$A$73,A3,Trazabilidad!$I$2:$I$73,"<>") -> 0 | J3: =IF(E3=0,0,H3/E3) -> 1 | K3: =IF(G3=0,"Falta escenario negativo",IF(F3=0,"Falta escenario positivo",IF(H3<E3,"Faltan casos de prueba","OK"))) -> OK
A4: RF-03 | B4: HU-03 | C4: M | D4: Sí | E4: =COUNTIF(Trazabilidad!$A$2:$A$73,A4) -> 3 | F4: =COUNTIFS(Trazabilidad!$A$2:$A$73,A4,Trazabilidad!$G$2:$G$73,"Positivo") -> 2 | G4: =COUNTIFS(Trazabilidad!$A$2:$A$73,A4,Trazabilidad!$G$2:$G$73,"Negativo") -> 1 | H4: =COUNTIFS(Trazabilidad!$A$2:$A$73,A4,Trazabilidad!$H$2:$H$73,"<>") -> 3 | I4: =COUNTIFS(Trazabilidad!$A$2:$A$73,A4,Trazabilidad!$I$2:$I$73,"<>") -> 0 | J4: =IF(E4=0,0,H4/E4) -> 1 | K4: =IF(G4=0,"Falta escenario negativo",IF(F4=0,"Falta escenario positivo",IF(H4<E4,"Faltan casos de prueba","OK"))) -> OK
A5: RF-04 | B5: HU-04 | C5: M | D5: Sí | E5: =COUNTIF(Trazabilidad!$A$2:$A$73,A5) -> 5 | F5: =COUNTIFS(Trazabilidad!$A$2:$A$73,A5,Trazabilidad!$G$2:$G$73,"Positivo") -> 2 | G5: =COUNTIFS(Trazabilidad!$A$2:$A$73,A5,Trazabilidad!$G$2:$G$73,"Negativo") -> 3 | H5: =COUNTIFS(Trazabilidad!$A$2:$A$73,A5,Trazabilidad!$H$2:$H$73,"<>") -> 3 | I5: =COUNTIFS(Trazabilidad!$A$2:$A$73,A5,Trazabilidad!$I$2:$I$73,"<>") -> 0 | J5: =IF(E5=0,0,H5/E5) -> 0.6 | K5: =IF(G5=0,"Falta escenario negativo",IF(F5=0,"Falta escenario positivo",IF(H5<E5,"Faltan casos de prueba","OK"))) -> Faltan casos de prueba
A6: RF-05 | B6: HU-05 | C6: M | D6: Sí | E6: =COUNTIF(Trazabilidad!$A$2:$A$73,A6) -> 4 | F6: =COUNTIFS(Trazabilidad!$A$2:$A$73,A6,Trazabilidad!$G$2:$G$73,"Positivo") -> 3 | G6: =COUNTIFS(Trazabilidad!$A$2:$A$73,A6,Trazabilidad!$G$2:$G$73,"Negativo") -> 1 | H6: =COUNTIFS(Trazabilidad!$A$2:$A$73,A6,Trazabilidad!$H$2:$H$73,"<>") -> 4 | I6: =COUNTIFS(Trazabilidad!$A$2:$A$73,A6,Trazabilidad!$I$2:$I$73,"<>") -> 0 | J6: =IF(E6=0,0,H6/E6) -> 1 | K6: =IF(G6=0,"Falta escenario negativo",IF(F6=0,"Falta escenario positivo",IF(H6<E6,"Faltan casos de prueba","OK"))) -> OK
A7: RF-06 | B7: HU-06 | C7: M | D7: Sí | E7: =COUNTIF(Trazabilidad!$A$2:$A$73,A7) -> 4 | F7: =COUNTIFS(Trazabilidad!$A$2:$A$73,A7,Trazabilidad!$G$2:$G$73,"Positivo") -> 2 | G7: =COUNTIFS(Trazabilidad!$A$2:$A$73,A7,Trazabilidad!$G$2:$G$73,"Negativo") -> 2 | H7: =COUNTIFS(Trazabilidad!$A$2:$A$73,A7,Trazabilidad!$H$2:$H$73,"<>") -> 4 | I7: =COUNTIFS(Trazabilidad!$A$2:$A$73,A7,Trazabilidad!$I$2:$I$73,"<>") -> 0 | J7: =IF(E7=0,0,H7/E7) -> 1 | K7: =IF(G7=0,"Falta escenario negativo",IF(F7=0,"Falta escenario positivo",IF(H7<E7,"Faltan casos de prueba","OK"))) -> OK
A8: RF-07 | B8: HU-07 | C8: M | D8: Sí | E8: =COUNTIF(Trazabilidad!$A$2:$A$73,A8) -> 3 | F8: =COUNTIFS(Trazabilidad!$A$2:$A$73,A8,Trazabilidad!$G$2:$G$73,"Positivo") -> 2 | G8: =COUNTIFS(Trazabilidad!$A$2:$A$73,A8,Trazabilidad!$G$2:$G$73,"Negativo") -> 1 | H8: =COUNTIFS(Trazabilidad!$A$2:$A$73,A8,Trazabilidad!$H$2:$H$73,"<>") -> 2 | I8: =COUNTIFS(Trazabilidad!$A$2:$A$73,A8,Trazabilidad!$I$2:$I$73,"<>") -> 0 | J8: =IF(E8=0,0,H8/E8) -> 0.66666667 | K8: =IF(G8=0,"Falta escenario negativo",IF(F8=0,"Falta escenario positivo",IF(H8<E8,"Faltan casos de prueba","OK"))) -> Faltan casos de prueba
A9: RF-08 | B9: HU-08 | C9: M | D9: Sí | E9: =COUNTIF(Trazabilidad!$A$2:$A$73,A9) -> 4 | F9: =COUNTIFS(Trazabilidad!$A$2:$A$73,A9,Trazabilidad!$G$2:$G$73,"Positivo") -> 1 | G9: =COUNTIFS(Trazabilidad!$A$2:$A$73,A9,Trazabilidad!$G$2:$G$73,"Negativo") -> 3 | H9: =COUNTIFS(Trazabilidad!$A$2:$A$73,A9,Trazabilidad!$H$2:$H$73,"<>") -> 4 | I9: =COUNTIFS(Trazabilidad!$A$2:$A$73,A9,Trazabilidad!$I$2:$I$73,"<>") -> 0 | J9: =IF(E9=0,0,H9/E9) -> 1 | K9: =IF(G9=0,"Falta escenario negativo",IF(F9=0,"Falta escenario positivo",IF(H9<E9,"Faltan casos de prueba","OK"))) -> OK
A10: RF-09 | B10: HU-12 | C10: S | D10: No | E10: =COUNTIF(Trazabilidad!$A$2:$A$73,A10) -> 4 | F10: =COUNTIFS(Trazabilidad!$A$2:$A$73,A10,Trazabilidad!$G$2:$G$73,"Positivo") -> 2 | G10: =COUNTIFS(Trazabilidad!$A$2:$A$73,A10,Trazabilidad!$G$2:$G$73,"Negativo") -> 2 | H10: =COUNTIFS(Trazabilidad!$A$2:$A$73,A10,Trazabilidad!$H$2:$H$73,"<>") -> 0 | I10: =COUNTIFS(Trazabilidad!$A$2:$A$73,A10,Trazabilidad!$I$2:$I$73,"<>") -> 0 | J10: =IF(E10=0,0,H10/E10) -> 0 | K10: =IF(G10=0,"Falta escenario negativo",IF(F10=0,"Falta escenario positivo",IF(H10<E10,"Faltan casos de prueba","OK"))) -> Faltan casos de prueba
A11: RF-10 | B11: HU-10 | C11: M | D11: Sí | E11: =COUNTIF(Trazabilidad!$A$2:$A$73,A11) -> 4 | F11: =COUNTIFS(Trazabilidad!$A$2:$A$73,A11,Trazabilidad!$G$2:$G$73,"Positivo") -> 3 | G11: =COUNTIFS(Trazabilidad!$A$2:$A$73,A11,Trazabilidad!$G$2:$G$73,"Negativo") -> 1 | H11: =COUNTIFS(Trazabilidad!$A$2:$A$73,A11,Trazabilidad!$H$2:$H$73,"<>") -> 4 | I11: =COUNTIFS(Trazabilidad!$A$2:$A$73,A11,Trazabilidad!$I$2:$I$73,"<>") -> 0 | J11: =IF(E11=0,0,H11/E11) -> 1 | K11: =IF(G11=0,"Falta escenario negativo",IF(F11=0,"Falta escenario positivo",IF(H11<E11,"Faltan casos de prueba","OK"))) -> OK
A12: RF-11 | B12: HU-11 | C12: M | D12: Sí | E12: =COUNTIF(Trazabilidad!$A$2:$A$73,A12) -> 3 | F12: =COUNTIFS(Trazabilidad!$A$2:$A$73,A12,Trazabilidad!$G$2:$G$73,"Positivo") -> 2 | G12: =COUNTIFS(Trazabilidad!$A$2:$A$73,A12,Trazabilidad!$G$2:$G$73,"Negativo") -> 1 | H12: =COUNTIFS(Trazabilidad!$A$2:$A$73,A12,Trazabilidad!$H$2:$H$73,"<>") -> 3 | I12: =COUNTIFS(Trazabilidad!$A$2:$A$73,A12,Trazabilidad!$I$2:$I$73,"<>") -> 0 | J12: =IF(E12=0,0,H12/E12) -> 1 | K12: =IF(G12=0,"Falta escenario negativo",IF(F12=0,"Falta escenario positivo",IF(H12<E12,"Faltan casos de prueba","OK"))) -> OK
A13: RF-12 | B13: HU-13 | C13: S | D13: No | E13: =COUNTIF(Trazabilidad!$A$2:$A$73,A13) -> 3 | F13: =COUNTIFS(Trazabilidad!$A$2:$A$73,A13,Trazabilidad!$G$2:$G$73,"Positivo") -> 2 | G13: =COUNTIFS(Trazabilidad!$A$2:$A$73,A13,Trazabilidad!$G$2:$G$73,"Negativo") -> 1 | H13: =COUNTIFS(Trazabilidad!$A$2:$A$73,A13,Trazabilidad!$H$2:$H$73,"<>") -> 0 | I13: =COUNTIFS(Trazabilidad!$A$2:$A$73,A13,Trazabilidad!$I$2:$I$73,"<>") -> 0 | J13: =IF(E13=0,0,H13/E13) -> 0 | K13: =IF(G13=0,"Falta escenario negativo",IF(F13=0,"Falta escenario positivo",IF(H13<E13,"Faltan casos de prueba","OK"))) -> Faltan casos de prueba
... A19: RF-18 | B19: HU-18 | C19: C | D19: No | E19: =COUNTIF(Trazabilidad!$A$2:$A$73,A19) -> 2 | F19: =COUNTIFS(Trazabilidad!$A$2:$A$73,A19,Trazabilidad!$G$2:$G$73,"Positivo") -> 1 | G19: =COUNTIFS(Trazabilidad!$A$2:$A$73,A19,Trazabilidad!$G$2:$G$73,"Negativo") -> 1 | H19: =COUNTIFS(Trazabilidad!$A$2:$A$73,A19,Trazabilidad!$H$2:$H$73,"<>") -> 0 | I19: =COUNTIFS(Trazabilidad!$A$2:$A$73,A19,Trazabilidad!$I$2:$I$73,"<>") -> 0 | J19: =IF(E19=0,0,H19/E19) -> 0 | K19: =IF(G19=0,"Falta escenario negativo",IF(F19=0,"Falta escenario positivo",IF(H19<E19,"Faltan casos de prueba","OK"))) -> Faltan casos de prueba
A21: Total | E21: =SUM(E2:E19) -> 72 | F21: =SUM(F2:F19) -> 37 | G21: =SUM(G2:G19) -> 35 | H21: =SUM(H2:H19) -> 42 | I21: =SUM(I2:I19) -> 0 | J21: =IF(E21=0,0,H21/E21) -> 0.58333333
A22: Solo parcial (v0.5.0) | E22: =SUMIF($D$2:$D$19,"Sí",E2:E19) -> 52 | F22: =SUMIF($D$2:$D$19,"Sí",F2:F19) -> 26 | G22: =SUMIF($D$2:$D$19,"Sí",G2:G19) -> 26 | H22: =SUMIF($D$2:$D$19,"Sí",H2:H19) -> 42 | I22: =SUMIF($D$2:$D$19,"Sí",I2:I19) -> 0 | J22: =IF(E22=0,0,H22/E22) -> 0.80769231

Sheet CP transversales
A1: CP | B1: Caso | C1: Resultado esperado | D1: Requisito no funcional (SRS sección 5)
A2: CP-041 | B2: Cada endpoint de /api/v1 sin token | C2: 401 (excepto registro y login) | D2: Seguridad: autorización por rol en cada endpoint
A3: CP-042 | B3: Cada endpoint con un rol sin permiso | C3: 403 | D3: Seguridad: autorización por rol en cada endpoint
A4: CP-043 | B4: Respuestas de error | C4: Formato application/problem+json | D4: Compatibilidad: contrato de la API y convenciones de error
A5: CP-044 | B5: Logs de login y registro | C5: Sin contraseñas ni tokens | D5: Operabilidad: logs sin datos sensibles
A6: CP-045 | B6: Repositorio | C6: Sin secretos (escaneo en CI) | D6: Seguridad: sin secretos en el repositorio
A7: CP-046 | B7: docker compose up en máquina limpia | C7: App, BD y Mailpit levantan | D7: Portabilidad
A8: CP-047 | B8: GET /actuator/health | C8: UP | D8: Fiabilidad: healthcheck
A9: CP-048 | B9: Migraciones Flyway en BD vacía | C9: Se aplican V1..Vn y Hibernate validate no reporta diferencias | D9: Fiabilidad / Mantenibilidad: migraciones versionadas
